Workbook

Sheet Base
A1: Grupo | B1: Rua | C1: Valor | D1: KM | E1: Bairro | F1: CEP | G1: Filtro
A2: 13 | B2: BASALTO | C2: 13 | D2: 0.6 | E2: Cohab | F2: 21730-230 | G2: =IF(Consulta!$B$1="", "", IF(OR(IFERROR(SEARCH(Consulta!$B$1,B2),0)>0,IFERROR(SEARCH(Consulta!$B$1,E2),0)>0,IFERROR(SEARCH(Consulta!$B$1,F2),0)>0), MAX($G$1:G1)+1, "")) | H2: =A2=C2 -> TRUE
A3: 13 | B3: CARLOS WENCESLEU ATÉ O PARQUE | C3: 13 | D3: 0,7 | E3: Realengo | F3: 21715-320 | G3: =IF(Consulta!$B$1="", "", IF(OR(IFERROR(SEARCH(Consulta!$B$1,B3),0)>0,IFERROR(SEARCH(Consulta!$B$1,E3),0)>0,IFERROR(SEARCH(Consulta!$B$1,F3),0)>0), MAX($G$1:G1)+1, "")) | H3: =A3=C3 -> TRUE
A4: 13 | B4: CASA DE PARTO | C4: 13 | D4: 0.3 | E4: Realengo | F4: 21710-231 | G4: =IF(Consulta!$B$1="", "", IF(OR(IFERROR(SEARCH(Consulta!$B$1,B4),0)>0,IFERROR(SEARCH(Consulta!$B$1,E4),0)>0,IFERROR(SEARCH(Consulta!$B$1,F4),0)>0), MAX($G$1:G3)+1, "")) | H4: =A4=C4 -> TRUE
A5: 13 | B5: CIRANDA | C5: 13 | D5: 0.6 | E5: Cohab | F5: 21730-230 | G5: =IF(Consulta!$B$1="", "", IF(OR(IFERROR(SEARCH(Consulta!$B$1,B5),0)>0,IFERROR(SEARCH(Consulta!$B$1,E5),0)>0,IFERROR(SEARCH(Consulta!$B$1,F5),0)>0), MAX($G$1:G4)+1, "")) | H5: =A5=C5 -> TRUE
A6: 13 | B6: CITARA | C6: 13 | D6: 0.6 | E6: Cohab | F6: 21730-230 | G6: =IF(Consulta!$B$1="", "", IF(OR(IFERROR(SEARCH(Consulta!$B$1,B6),0)>0,IFERROR(SEARCH(Consulta!$B$1,E6),0)>0,IFERROR(SEARCH(Consulta!$B$1,F6),0)>0), MAX($G$1:G5)+1, "")) | H6: =A6=C6 -> TRUE
A7: 13 | B7: COHAB | C7: 13 | D7: 1.0 | E7: Realengo | F7: 21730-230 | G7: =IF(Consulta!$B$1="", "", IF(OR(IFERROR(SEARCH(Consulta!$B$1,B7),0)>0,IFERROR(SEARCH(Consulta!$B$1,E7),0)>0,IFERROR(SEARCH(Consulta!$B$1,F7),0)>0), MAX($G$1:G6)+1, "")) | H7: =A7=C7 -> TRUE
A8: 13 | B8: CURIO | C8: 13 | D8: 0.6 | E8: Cohab | F8: 21730-230 | G8: =IF(Consulta!$B$1="", "", IF(OR(IFERROR(SEARCH(Consulta!$B$1,B8),0)>0,IFERROR(SEARCH(Consulta!$B$1,E8),0)>0,IFERROR(SEARCH(Consulta!$B$1,F8),0)>0), MAX($G$1:G7)+1, "")) | H8: =A8=C8 -> TRUE
A9: 13 | B9: DONA OLIMPIA | C9: 13 | D9: 0.6 | E9: Cohab | F9: 21730-230 | G9: =IF(Consulta!$B$1="", "", IF(OR(IFERROR(SEARCH(Consulta!$B$1,B9),0)>0,IFERROR(SEARCH(Consulta!$B$1,E9),0)>0,IFERROR(SEARCH(Consulta!$B$1,F9),0)>0), MAX($G$1:G8)+1, "")) | H9: =A9=C9 -> TRUE
A10: 13 | B10: DOUTOR LESSA | C10: 13 | D10: 0.6 | E10: Realengo | F10: 21710-270 | G10: =IF(Consulta!$B$1="", "", IF(OR(IFERROR(SEARCH(Consulta!$B$1,B10),0)>0,IFERROR(SEARCH(Consulta!$B$1,E10),0)>0,IFERROR(SEARCH(Consulta!$B$1,F10),0)>0), MAX($G$1:G9)+1, "")) | H10: =A10=C10 -> TRUE
A11: 13 | B11: ESPARDARTE | C11: 13 | D11: 0.6 | E11: Cohab | F11: 21730-230 | G11: =IF(Consulta!$B$1="", "", IF(OR(IFERROR(SEARCH(Consulta!$B$1,B11),0)>0,IFERROR(SEARCH(Consulta!$B$1,E11),0)>0,IFERROR(SEARCH(Consulta!$B$1,F11),0)>0), MAX($G$1:G9)+1, "")) | H11: =A11=C11 -> TRUE
A12: 13 | B12: GAZELA | C12: 13 | D12: 0.6 | E12: Cohab | F12: 21730-230 | G12: =IF(Consulta!$B$1="", "", IF(OR(IFERROR(SEARCH(Consulta!$B$1,B12),0)>0,IFERROR(SEARCH(Consulta!$B$1,E12),0)>0,IFERROR(SEARCH(Consulta!$B$1,F12),0)>0), MAX($G$1:G11)+1, "")) | H12: =A12=C12 -> TRUE
A13: 13 | B13: GENERAL RAPOSO | C13: 13 | D13: 1,1 | E13: Realengo | F13: 21710-260 | G13: =IF(Consulta!$B$1="", "", IF(OR(IFERROR(SEARCH(Consulta!$B$1,B13),0)>0,IFERROR(SEARCH(Consulta!$B$1,E13),0)>0,IFERROR(SEARCH(Consulta!$B$1,F13),0)>0), MAX($G$1:G12)+1, "")) | H13: =A13=C13 -> TRUE
A14: 13 | B14: HELENA | C14: 13 | D14: 0.4 | E14: Realengo | F14: 21710-250 | G14: =IF(Consulta!$B$1="", "", IF(OR(IFERROR(SEARCH(Consulta!$B$1,B14),0)>0,IFERROR(SEARCH(Consulta!$B$1,E14),0)>0,IFERROR(SEARCH(Consulta!$B$1,F14),0)>0), MAX($G$1:G13)+1, "")) | H14: =A14=C14 -> TRUE
A15: 13 | B15: PARANAGUA | C15: 13 | D15: 0.5 | E15: Realengo | F15: 21710-690 | G15: =IF(Consulta!$B$1="", "", IF(OR(IFERROR(SEARCH(Consulta!$B$1,B15),0)>0,IFERROR(SEARCH(Consulta!$B$1,E15),0)>0,IFERROR(SEARCH(Consulta!$B$1,F15),0)>0), MAX($G$1:G14)+1, "")) | H15: =A15=C15 -> TRUE
A16: 13 | B16: PARAPUÃ ATÉ PREDIOS (383) | C16: 13 | D16: 1 | E16: Realengo - Cohab | F16: 21765-050 | G16: =IF(Consulta!$B$1="", "", IF(OR(IFERROR(SEARCH(Consulta!$B$1,B16),0)>0,IFERROR(SEARCH(Consulta!$B$1,E16),0)>0,IFERROR(SEARCH(Consulta!$B$1,F16),0)>0), MAX($G$1:G15)+1, "")) | H16: =A16=C16 -> TRUE
A17: 13 | B17: PAULA NEI | C17: 13 | D17: 0.6 | E17: Cohab | F17: 21730-230 | G17: =IF(Consulta!$B$1="", "", IF(OR(IFERROR(SEARCH(Consulta!$B$1,B17),0)>0,IFERROR(SEARCH(Consulta!$B$1,E17),0)>0,IFERROR(SEARCH(Consulta!$B$1,F17),0)>0), MAX($G$1:G16)+1, "")) | H17: =A17=C17 -> TRUE
A18: 13 | B18: PONTALINA | C18: 13 | D18: 0.5 | E18: Realengo | F18: 21710-150 | G18: =IF(Consulta!$B$1="", "", IF(OR(IFERROR(SEARCH(Consulta!$B$1,B18),0)>0,IFERROR(SEARCH(Consulta!$B$1,E18),0)>0,IFERROR(SEARCH(Consulta!$B$1,F18),0)>0), MAX($G$1:G17)+1, "")) | H18: =A18=C18 -> TRUE
A19: 13 | B19: RERITUBA | C19: 13 | D19: 0.9 | E19: Realengo | F19: 21710-140 | G19: =IF(Consulta!$B$1="", "", IF(OR(IFERROR(SEARCH(Consulta!$B$1,B19),0)>0,IFERROR(SEARCH(Consulta!$B$1,E19),0)>0,IFERROR(SEARCH(Consulta!$B$1,F19),0)>0), MAX($G$1:G18)+1, "")) | H19: =A19=C19 -> TRUE
A20: 13 | B20: RUA DOS OPERARIOS | C20: 13 | D20: 0.8 | E20: Realengo | F20: 21710-310 | G20: =IF(Consulta!$B$1="", "", IF(OR(IFERROR(SEARCH(Consulta!$B$1,B20),0)>0,IFERROR(SEARCH(Consulta!$B$1,E20),0)>0,IFERROR(SEARCH(Consulta!$B$1,F20),0)>0), MAX($G$1:G19)+1, "")) | H20: =A20=C20 -> TRUE
A21: 15 | B21: ANIBAL ESTEVES | C21: 15 | D21: 1 | E21: Realengo | F21: 21710-040 | G21: =IF(Consulta!$B$1="", "", IF(OR(IFERROR(SEARCH(Consulta!$B$1,B21),0)>0,IFERROR(SEARCH(Consulta!$B$1,E21),0)>0,IFERROR(SEARCH(Consulta!$B$1,F21),0)>0), MAX($G$1:G19)+1, "")) | H21: =A21=C21 -> TRUE
A22: 15 | B22: ARITIBA ATÉ A FARMACIA | C22: 15 | D22: 1,4 | E22: Limites - Realengo | F22: 21740-260 | G22: =IF(Consulta!$B$1="", "", IF(OR(IFERROR(SEARCH(Consulta!$B$1,B22),0)>0,IFERROR(SEARCH(Consulta!$B$1,E22),0)>0,IFERROR(SEARCH(Consulta!$B$1,F22),0)>0), MAX($G$1:G20)+1, "")) | H22: =A22=C22 -> TRUE
A23: 15 | B23: BANDEIRA DE MELO | C23: 15 | D23: 2.1 | E23: Jardim Novo | F23: 21760-010 | G23: =IF(Consulta!$B$1="", "", IF(OR(IFERROR(SEARCH(Consulta!$B$1,B23),0)>0,IFERROR(SEARCH(Consulta!$B$1,E23),0)>0,IFERROR(SEARCH(Consulta!$B$1,F23),0)>0), MAX($G$1:G22)+1, "")) | H23: =A23=C23 -> TRUE
A24: 15 | B24: BERNARDO ATÉ A GELATO | C24: 15 | D24: 1,2 | E24: Realengo | F24: 21740-250 | G24: =IF(Consulta!$B$1="", "", IF(OR(IFERROR(SEARCH(Consulta!$B$1,B24),0)>0,IFERROR(SEARCH(Consulta!$B$1,E24),0)>0,IFERROR(SEARCH(Consulta!$B$1,F24),0)>0), MAX($G$1:G23)+1, "")) | H24: =A24=C24 -> TRUE
A25: 15 | B25: CARLOS WENCESLEU | C25: 15 | D25: 1 | E25: Realengo | F25: 21715-320 | G25: =IF(Consulta!$B$1="", "", IF(OR(IFERROR(SEARCH(Consulta!$B$1,B25),0)>0,IFERROR(SEARCH(Consulta!$B$1,E25),0)>0,IFERROR(SEARCH(Consulta!$B$1,F25),0)>0), MAX($G$1:G22)+1, "")) | H25: =A25=C25 -> TRUE
A26: 15 | B26: CARUMBE | C26: 15 | D26: 2,1 | E26: Realengo | F26: 21740-210 | G26: =IF(Consulta!$B$1="", "", IF(OR(IFERROR(SEARCH(Consulta!$B$1,B26),0)>0,IFERROR(SEARCH(Consulta!$B$1,E26),0)>0,IFERROR(SEARCH(Consulta!$B$1,F26),0)>0), MAX($G$1:G25)+1, "")) | H26: =A26=C26 -> TRUE
A27: 15 | B27: CESAR | C27: 15 | D27: 1,1 | E27: Realengo | F27: 21740-200 | G27: =IF(Consulta!$B$1="", "", IF(OR(IFERROR(SEARCH(Consulta!$B$1,B27),0)>0,IFERROR(SEARCH(Consulta!$B$1,E27),0)>0,IFERROR(SEARCH(Consulta!$B$1,F27),0)>0), MAX($G$1:G26)+1, "")) | H27: =A27=C27 -> TRUE
A28: 15 | B28: CORREA TEIXEIRA | C28: 15 | D28: 1,1 | E28: Ligth | F28: 21740-200 | G28: =IF(Consulta!$B$1="", "", IF(OR(IFERROR(SEARCH(Consulta!$B$1,B28),0)>0,IFERROR(SEARCH(Consulta!$B$1,E28),0)>0,IFERROR(SEARCH(Consulta!$B$1,F28),0)>0), MAX($G$1:G27)+1, "")) | H28: =A28=C28 -> TRUE
A29: 15 | B29: COSTA RUBIM | C29: 15 | D29: 2.5 | E29: Realengo | F29: 21710-000 | G29: =IF(Consulta!$B$1="", "", IF(OR(IFERROR(SEARCH(Consulta!$B$1,B29),0)>0,IFERROR(SEARCH(Consulta!$B$1,E29),0)>0,IFERROR(SEARCH(Consulta!$B$1,F29),0)>0), MAX($G$1:G28)+1, "")) | H29: =A29=C29 -> TRUE
A30: 15 | B30: DR. ORELY | C30: 15 | D30: 0.8 | E30: Realengo | F30: 21710-330 | G30: =IF(Consulta!$B$1="", "", IF(OR(IFERROR(SEARCH(Consulta!$B$1,B30),0)>0,IFERROR(SEARCH(Consulta!$B$1,E30),0)>0,IFERROR(SEARCH(Consulta!$B$1,F30),0)>0), MAX($G$1:G29)+1, "")) | H30: =A30=C30 -> TRUE
A31: 15 | B31: FREDERICO FAULHABER ANTES CAMPO SÃO LUIS | C31: 15 | D31: 2 | E31: Piraquara | F31: 21760-240 | G31: =IF(Consulta!$B$1="", "", IF(OR(IFERROR(SEARCH(Consulta!$B$1,B31),0)>0,IFERROR(SEARCH(Consulta!$B$1,E31),0)>0,IFERROR(SEARCH(Consulta!$B$1,F31),0)>0), MAX($G$1:G30)+1, "")) | H31: =A31=C31 -> TRUE
A32: 15 | B32: FREI MIGUEL | C32: 15 | D32: 2,2 | E32: Realengo | F32: 21740-170 | G32: =IF(Consulta!$B$1="", "", IF(OR(IFERROR(SEARCH(Consulta!$B$1,B32),0)>0,IFERROR(SEARCH(Consulta!$B$1,E32),0)>0,IFERROR(SEARCH(Consulta!$B$1,F32),0)>0), MAX($G$1:G31)+1, "")) | H32: =A32=C32 -> TRUE
A33: 15 | B33: GENERAL AZEREDO | C33: 15 | D33: 0,7 | E33: Realengo | F33: 21740-160 | G33: =IF(Consulta!$B$1="", "", IF(OR(IFERROR(SEARCH(Consulta!$B$1,B33),0)>0,IFERROR(SEARCH(Consulta!$B$1,E33),0)>0,IFERROR(SEARCH(Consulta!$B$1,F33),0)>0), MAX($G$1:G32)+1, "")) | H33: =A33=C33 -> TRUE
A34: 15 | B34: GENERAL ZESEFREDO | C34: 15 | D34: 2.1 | E34: Realengo | F34: 21715-062 | G34: =IF(Consulta!$B$1="", "", IF(OR(IFERROR(SEARCH(Consulta!$B$1,B34),0)>0,IFERROR(SEARCH(Consulta!$B$1,E34),0)>0,IFERROR(SEARCH(Consulta!$B$1,F34),0)>0), MAX($G$1:G33)+1, "")) | H34: =A34=C34 -> TRUE
A35: 15 | B35: IDEAL | C35: 15 | D35: 0,8 | E35: Realengo | F35: 21740-150 | G35: =IF(Consulta!$B$1="", "", IF(OR(IFERROR(SEARCH(Consulta!$B$1,B35),0)>0,IFERROR(SEARCH(Consulta!$B$1,E35),0)>0,IFERROR(SEARCH(Consulta!$B$1,F35),0)>0), MAX($G$1:G34)+1, "")) | H35: =A35=C35 -> TRUE
A36: 15 | B36: IMPERADOR | C36: 15 | D36: 1,4 | E36: Realengo | F36: 21740-260 | G36: =IF(Consulta!$B$1="", "", IF(OR(IFERROR(SEARCH(Consulta!$B$1,B36),0)>0,IFERROR(SEARCH(Consulta!$B$1,E36),0)>0,IFERROR(SEARCH(Consulta!$B$1,F36),0)>0), MAX($G$1:G35)+1, "")) | H36: =A36=C36 -> TRUE
A37: 15 | B37: IMPERATRIZ | C37: 15 | D37: 0.6 | E37: Realengo | F37: 21710-320 | G37: =IF(Consulta!$B$1="", "", IF(OR(IFERROR(SEARCH(Consulta!$B$1,B37),0)>0,IFERROR(SEARCH(Consulta!$B$1,E37),0)>0,IFERROR(SEARCH(Consulta!$B$1,F37),0)>0), MAX($G$1:G36)+1, "")) | H37: =A37=C37 -> TRUE
A38: 15 | B38: JEQUITINHONHA | C38: 15 | D38: 2.2 | E38: Realengo | F38: 21755-360 | G38: =IF(Consulta!$B$1="", "", IF(OR(IFERROR(SEARCH(Consulta!$B$1,B38),0)>0,IFERROR(SEARCH(Consulta!$B$1,E38),0)>0,IFERROR(SEARCH(Consulta!$B$1,F38),0)>0), MAX($G$1:G37)+1, "")) | H38: =A38=C38 -> TRUE
A39: 15 | B39: JOSE MARIA DE ABREU (RUA 1) | C39: 15 | D39: 2.1 | E39: Realengo | F39: 21755-260 | G39: =IF(Consulta!$B$1="", "", IF(OR(IFERROR(SEARCH(Consulta!$B$1,B39),0)>0,IFERROR(SEARCH(Consulta!$B$1,E39),0)>0,IFERROR(SEARCH(Consulta!$B$1,F39),0)>0), MAX($G$1:G38)+1, "")) | H39: =A39=C39 -> TRUE
A40: 15 | B40: LOMAS VALENTINA | C40: 15 | D40: 1.5 | E40: Realengo | F40: 21721-280 | G40: =IF(Consulta!$B$1="", "", IF(OR(IFERROR(SEARCH(Consulta!$B$1,B40),0)>0,IFERROR(SEARCH(Consulta!$B$1,E40),0)>0,IFERROR(SEARCH(Consulta!$B$1,F40),0)>0), MAX($G$1:G39)+1, "")) | H40: =A40=C40 -> TRUE
...

Sheet Consulta
A1: Digite sua busca: | C1: =IF(B1="", "", IF(MAX(Base!$G:$G)=0, "Dados não encontrados !!!", "Resultado(s) abaixo :"))
A2: Digite qualquer parte do nome da rua, do bairro ou do CEP, no campo acima amarelo.
A3: Grupo | B3: Rua | C3: Valor | D3: KM | E3: Bairro | F3: CEP
A4: =IFERROR(INDEX(Base!A:A,MATCH(ROW(A1),Base!$G:$G,0)),"") | B4: =IFERROR(INDEX(Base!B:B,MATCH(ROW(B1),Base!$G:$G,0)),"") | C4: =IFERROR(INDEX(Base!C:C,MATCH(ROW(C1),Base!$G:$G,0)),"") | D4: =IFERROR(INDEX(Base!D:D,MATCH(ROW(D1),Base!$G:$G,0)),"") | E4: =IFERROR(INDEX(Base!E:E,MATCH(ROW(E1),Base!$G:$G,0)),"") | F4: =IFERROR(INDEX(Base!F:F,MATCH(ROW(F1),Base!$G:$G,0)),"")
A5: =IFERROR(INDEX(Base!A:A,MATCH(ROW(A2),Base!$G:$G,0)),"") | B5: =IFERROR(INDEX(Base!B:B,MATCH(ROW(B2),Base!$G:$G,0)),"") | C5: =IFERROR(INDEX(Base!C:C,MATCH(ROW(C2),Base!$G:$G,0)),"") | D5: =IFERROR(INDEX(Base!D:D,MATCH(ROW(D2),Base!$G:$G,0)),"") | E5: =IFERROR(INDEX(Base!E:E,MATCH(ROW(E2),Base!$G:$G,0)),"") | F5: =IFERROR(INDEX(Base!F:F,MATCH(ROW(F2),Base!$G:$G,0)),"")
A6: =IFERROR(INDEX(Base!A:A,MATCH(ROW(A3),Base!$G:$G,0)),"") | B6: =IFERROR(INDEX(Base!B:B,MATCH(ROW(B3),Base!$G:$G,0)),"") | C6: =IFERROR(INDEX(Base!C:C,MATCH(ROW(C3),Base!$G:$G,0)),"") | D6: =IFERROR(INDEX(Base!D:D,MATCH(ROW(D3),Base!$G:$G,0)),"") | E6: =IFERROR(INDEX(Base!E:E,MATCH(ROW(E3),Base!$G:$G,0)),"") | F6: =IFERROR(INDEX(Base!F:F,MATCH(ROW(F3),Base!$G:$G,0)),"")
A7: =IFERROR(INDEX(Base!A:A,MATCH(ROW(A4),Base!$G:$G,0)),"") | B7: =IFERROR(INDEX(Base!B:B,MATCH(ROW(B4),Base!$G:$G,0)),"") | C7: =IFERROR(INDEX(Base!C:C,MATCH(ROW(C4),Base!$G:$G,0)),"") | D7: =IFERROR(INDEX(Base!D:D,MATCH(ROW(D4),Base!$G:$G,0)),"") | E7: =IFERROR(INDEX(Base!E:E,MATCH(ROW(E4),Base!$G:$G,0)),"") | F7: =IFERROR(INDEX(Base!F:F,MATCH(ROW(F4),Base!$G:$G,0)),"")
A8: =IFERROR(INDEX(Base!A:A,MATCH(ROW(A5),Base!$G:$G,0)),"") | B8: =IFERROR(INDEX(Base!B:B,MATCH(ROW(B5),Base!$G:$G,0)),"") | C8: =IFERROR(INDEX(Base!C:C,MATCH(ROW(C5),Base!$G:$G,0)),"") | D8: =IFERROR(INDEX(Base!D:D,MATCH(ROW(D5),Base!$G:$G,0)),"") | E8: =IFERROR(INDEX(Base!E:E,MATCH(ROW(E5),Base!$G:$G,0)),"") | F8: =IFERROR(INDEX(Base!F:F,MATCH(ROW(F5),Base!$G:$G,0)),"")
A9: =IFERROR(INDEX(Base!A:A,MATCH(ROW(A6),Base!$G:$G,0)),"") | B9: =IFERROR(INDEX(Base!B:B,MATCH(ROW(B6),Base!$G:$G,0)),"") | C9: =IFERROR(INDEX(Base!C:C,MATCH(ROW(C6),Base!$G:$G,0)),"") | D9: =IFERROR(INDEX(Base!D:D,MATCH(ROW(D6),Base!$G:$G,0)),"") | E9: =IFERROR(INDEX(Base!E:E,MATCH(ROW(E6),Base!$G:$G,0)),"") | F9: =IFERROR(INDEX(Base!F:F,MATCH(ROW(F6),Base!$G:$G,0)),"")
A10: =IFERROR(INDEX(Base!A:A,MATCH(ROW(A7),Base!$G:$G,0)),"") | B10: =IFERROR(INDEX(Base!B:B,MATCH(ROW(B7),Base!$G:$G,0)),"") | C10: =IFERROR(INDEX(Base!C:C,MATCH(ROW(C7),Base!$G:$G,0)),"") | D10: =IFERROR(INDEX(Base!D:D,MATCH(ROW(D7),Base!$G:$G,0)),"") | E10: =IFERROR(INDEX(Base!E:E,MATCH(ROW(E7),Base!$G:$G,0)),"") | F10: =IFERROR(INDEX(Base!F:F,MATCH(ROW(F7),Base!$G:$G,0)),"")
A11: =IFERROR(INDEX(Base!A:A,MATCH(ROW(A8),Base!$G:$G,0)),"") | B11: =IFERROR(INDEX(Base!B:B,MATCH(ROW(B8),Base!$G:$G,0)),"") | C11: =IFERROR(INDEX(Base!C:C,MATCH(ROW(C8),Base!$G:$G,0)),"") | D11: =IFERROR(INDEX(Base!D:D,MATCH(ROW(D8),Base!$G:$G,0)),"") | E11: =IFERROR(INDEX(Base!E:E,MATCH(ROW(E8),Base!$G:$G,0)),"") | F11: =IFERROR(INDEX(Base!F:F,MATCH(ROW(F8),Base!$G:$G,0)),"")
A12: =IFERROR(INDEX(Base!A:A,MATCH(ROW(A9),Base!$G:$G,0)),"") | B12: =IFERROR(INDEX(Base!B:B,MATCH(ROW(B9),Base!$G:$G,0)),"") | C12: =IFERROR(INDEX(Base!C:C,MATCH(ROW(C9),Base!$G:$G,0)),"") | D12: =IFERROR(INDEX(Base!D:D,MATCH(ROW(D9),Base!$G:$G,0)),"") | E12: =IFERROR(INDEX(Base!E:E,MATCH(ROW(E9),Base!$G:$G,0)),"") | F12: =IFERROR(INDEX(Base!F:F,MATCH(ROW(F9),Base!$G:$G,0)),"")
A13: =IFERROR(INDEX(Base!A:A,MATCH(ROW(A10),Base!$G:$G,0)),"") | B13: =IFERROR(INDEX(Base!B:B,MATCH(ROW(B10),Base!$G:$G,0)),"") | C13: =IFERROR(INDEX(Base!C:C,MATCH(ROW(C10),Base!$G:$G,0)),"") | D13: =IFERROR(INDEX(Base!D:D,MATCH(ROW(D10),Base!$G:$G,0)),"") | E13: =IFERROR(INDEX(Base!E:E,MATCH(ROW(E10),Base!$G:$G,0)),"") | F13: =IFERROR(INDEX(Base!F:F,MATCH(ROW(F10),Base!$G:$G,0)),"")
A14: =IFERROR(INDEX(Base!A:A,MATCH(ROW(A11),Base!$G:$G,0)),"") | B14: =IFERROR(INDEX(Base!B:B,MATCH(ROW(B11),Base!$G:$G,0)),"") | C14: =IFERROR(INDEX(Base!C:C,MATCH(ROW(C11),Base!$G:$G,0)),"") | D14: =IFERROR(INDEX(Base!D:D,MATCH(ROW(D11),Base!$G:$G,0)),"") | E14: =IFERROR(INDEX(Base!E:E,MATCH(ROW(E11),Base!$G:$G,0)),"") | F14: =IFERROR(INDEX(Base!F:F,MATCH(ROW(F11),Base!$G:$G,0)),"")
A15: =IFERROR(INDEX(Base!A:A,MATCH(ROW(A12),Base!$G:$G,0)),"") | B15: =IFERROR(INDEX(Base!B:B,MATCH(ROW(B12),Base!$G:$G,0)),"") | C15: =IFERROR(INDEX(Base!C:C,MATCH(ROW(C12),Base!$G:$G,0)),"") | D15: =IFERROR(INDEX(Base!D:D,MATCH(ROW(D12),Base!$G:$G,0)),"") | E15: =IFERROR(INDEX(Base!E:E,MATCH(ROW(E12),Base!$G:$G,0)),"") | F15: =IFERROR(INDEX(Base!F:F,MATCH(ROW(F12),Base!$G:$G,0)),"")
... A154: =IFERROR(INDEX(Base!A:A,MATCH(ROW(A151),Base!$G:$G,0)),"") | B154: =IFERROR(INDEX(Base!B:B,MATCH(ROW(B151),Base!$G:$G,0)),"") | C154: =IFERROR(INDEX(Base!C:C,MATCH(ROW(C151),Base!$G:$G,0)),"") | D154: =IFERROR(INDEX(Base!D:D,MATCH(ROW(D151),Base!$G:$G,0)),"") | E154: =IFERROR(INDEX(Base!E:E,MATCH(ROW(E151),Base!$G:$G,0)),"") | F154: =IFERROR(INDEX(Base!F:F,MATCH(ROW(F151),Base!$G:$G,0)),"")
